Workbook
Name ChartValues: _xlfn.ANCHORARRAY(Sheet1!$D$63)
Name ChartYears: _xlfn.ANCHORARRAY(Sheet1!$D$62)

Sheet timeseries_yearmax
A1: station | B1: x | C1: y | D1: 2025 | E1: var_2025 | F1: 2024 | G1: var_2024 | H1: 2023 | I1: var_2023 | J1: 2022 | K1: var_2022 | L1: 2021 | M1: var_2021 | N1: 2020 | O1: var_2020 | P1: 2019 | Q1: var_2019 | R1: 2018 | S1: var_2018 | T1: 2017 | U1: var_2017 | V1: 2016 | W1: var_2016 | X1: 2015 | Y1: var_2015 | Z1: 2014 | AA1: var_2014 | AB1: 2013 | AC1: var_2013 | AD1: 2012 | AE1: var_2012 | AF1: 2011 | AG1: var_2011 | AH1: 2010 | AI1: var_2010 | AJ1: 2009 | AK1: var_2009 | AL1: 2008 | AM1: var_2008 | AN1: 2007 | AO1: var_2007 | AP1: 2006 | AQ1: var_2006 | AR1: 2005 | AS1: var_2005 | AT1: 2004 | AU1: var_2004 | AV1: 2003 | AW1: var_2003 | AX1: 2002 | AY1: var_2002 | AZ1: 2001 | BA1: var_2001 | BB1: 2000 | BC1: var_2000 | BD1: 1999 | BE1: var_1999 | BF1: 1998 | BG1: var_1998 | BH1: 1997 | BI1: var_1997 | BJ1: 1996 | BK1: var_1996 | BL1: 1995 | BM1: var_1995 | BN1: 1994 | BO1: var_1994 | BP1: 1993 | BQ1: var_1993 | BR1: 1992 | BS1: var_1992 | BT1: 1991 | BU1: var_1991 | BV1: 1990 | BW1: var_1990 | BX1: 1989 | BY1: var_1989 | BZ1: 1988 | CA1: var_1988 | CB1: 1987 | CC1: var_1987 | CD1: 1986 | CE1: var_1986 | CF1: 1985 | CG1: var_1985 | CH1: 1984 | CI1: var_1984 | CJ1: 1983 | CK1: var_1983 | CL1: 1982 | CM1: var_1982 | CN1: 1981 | CO1: var_1981 | CP1: 1980 | CQ1: var_1980 | CR1: 1979 | CS1: var_1979 | CT1: 1978 | CU1: var_1978 | CV1: 1977 | CW1: var_1977 | CX1: 1976 | CY1: var_1976 | CZ1: 1975 | DA1: var_1975 | DB1: 1974 | DC1: var_1974 | DD1: 1973 | DE1: var_1973 | DF1: 1972 | DG1: var_1972 | DH1: 1971 | DI1: var_1971 | DJ1: 1970 | DK1: var_1970 | DL1: 1969 | DM1: var_1969 | DN1: 1968 | DO1: var_1968 | DP1: 1967 | DQ1: var_1967 | DR1: 1966 | DS1: var_1966 | DT1: 1965 | DU1: var_1965 | DV1: 1964 | DW1: var_1964 | DX1: 1963 | DY1: var_1963 | DZ1: 1962 | EA1: var_1962 | EB1: 1961 | EC1: var_1961 | ED1: 1960 | EE1: var_1960 | EF1: 1959 | EG1: var_1959 | EH1: 1958 | EI1: var_1958 | EJ1: 1957 | EK1: var_1957 | EL1: 1956 | EM1: var_1956 | EN1: 1955 | EO1: var_1955 | EP1: 1954 | EQ1: var_1954 | ER1: 1953 | ES1: var_1953 | ET1: 1952 | EU1: var_1952 | EV1: 1951 | EW1: var_1951 | EX1: 1950 | EY1: var_1950
A2: Wolfson | B2: 177480 | C2: 660245 | D2: 2.4 | E2: 0.052872626 | F2: 2.0346686 | G2: 0.02095134 | H2: 1.6176612 | I2: 0.04485647 | J2: 1.6759288 | K2: 0.042405422 | L2: 1.5241341 | M2: 0.41337326 | N2: 1.5424586 | O2: 0.56965863 | P2: 0.89054939 | Q2: 0.46388374 | R2: 0.84066414 | S2: 0.35112836 | T2: 0.84153846 | U2: 0.12203489 | V2: 0.77615385 | W2: 0.048666745 | X2: 0.66094664 | Y2: 0.053191825 | Z2: 0.12137308 | AA2: 0.08545177 | AB2: 0.034259947 | AC2: 0.099052506 | AD2: -0.58849853 | AE2: 0.20109563 | AF2: -0.8682131 | AG2: 0.36417583 | AH2: -0.17510393 | AI2: 0.13067612 | AJ2: -1.1713263 | AK2: 2.8639626 | AL2: -0.10064541 | AM2: 0.13476897 | AN2: -0.3517256 | AO2: 0.56709029 | AP2: 0.069783256 | AQ2: 0.22858668 | AR2: -0.36695969 | AS2: 0.41883514 | AT2: -0.77191278 | AU2: 0.1321522 | AV2: -0.84637874 | AW2: 0.11603323 | AX2: -1.0935164 | AY2: 0.12943237 | AZ2: -0.6038973 | BA2: 0.17047877 | BB2: -0.27291927 | BC2: 0.22833546 | BD2: -0.00087064752 | BE2: 0.21893671 | BF2: 0.3323569 | BG2: 0.3029275 | BH2: 0.1401883 | BI2: 0.14209802 | BJ2: 0.46607251 | BK2: 0.1937477 | BL2: -0.009218151 | BM2: 0.22313048 | BN2: -0.76365258 | BO2: 0.20748787 | BP2: -0.60657728 | BQ2: 0.38805462 | BR2: -0.8603079 | BS2: 0.49246474 | BT2: -1.751375 | BU2: 0.4932646 | BV2: -1.8354423 | BW2: 0.44575266 | BX2: -1.694394 | BY2: 0.45378035 | BZ2: -1.6029717 | CA2: 0.6652322 | CB2: -1.6419811 | CC2: 0.62428604 | CD2: -1.5768339 | CE2: 0.54331425 | CF2: -1.2321055 | CG2: 0.41866498 | CH2: -1.0165511 | CI2: 0.35702607 | CJ2: -2.0912745 | CK2: 0.40004559 | CL2: -0.59698095 | CM2: 0.28042124 | CN2: 0.03329595 | CO2: 0.31982652 | CP2: 0.23121913 | CQ2: 0.33454 | CR2: -0.16732842 | CS2: 0.23366571 | CT2: 0.86148124 | CU2: 0.24768747 | CV2: 0.81505528 | CW2: 0.16288127 | CX2: 1.449929 | CY2: 0.10106459 | CZ2: 1.9214595 | DA2: 0.053464113 | DB2: 2.5329521 | DC2: 0.48907371 | DD2: 2.0559831 | DE2: 0.12664493 | DF2: 2.4198345 | DG2: 0.17988477 | DH2: 3.5983169 | DI2: 0.36249392 | DJ2: 2.6315203 | DK2: 0.74744811 | DL2: 2.4243692 | DM2: 0.10763967 | DN2: 2.5367917 | DO2: 0.078543018 | DP2: 2.3976515 | DQ2: 0.11350608 | DR2: 2.4277034 | DS2: 0.24163731 | DT2: 3.393991 | DU2: 1.6384947 | DV2: 2.0708957 | DW2: 0.19795878 | DX2: 1.0161386 | DY2: 0.11032936 | DZ2: 0.81308554 | EA2: 0.17260683 | EB2: 0.077314624 | EC2: 0.29363323 | ED2: -1.4501389 | EE2: 0.85631149 | EF2: -1.6021674 | EG2: 1.3615983 | EH2: -0.56496333 | EI2: 8.4035214 | EJ2: 2.9298802 | EK2: 2.6643108 | EL2: 1.4141312 | EM2: 3.5416129 | EN2: 1.1200762 | EO2: 2.9551289 | EP2: 1.4464352 | EQ2: 2.3437002 | ER2: 0.80219971 | ES2: 2.9176513 | ET2: 2.1103052 | EU2: 10.688911 | EV2: 2.5107132 | EW2: 32.982292 | EX2: 2.9776326 | EY2: 18.119946
A3: Shlavim | B3: 177980 | C3: 662360 | D3: 1.1 | E3: 0.08012332 | F3: 1.9063392 | G3: 0.083883309 | H3: 1.030907 | I3: 0.31835366 | J3: 1.9009145 | K3: 0.054594617 | L3: 1.3869107 | M3: 0.054745087 | N3: 0.29206031 | O3: 0.1389624 | P3: -0.20257656 | Q3: 0.37238237 | R3: 0.3406555 | S3: 0.94194917 | T3: 0.37675191 | U3: 0.04934264 | V3: 0.060955332 | W3: 0.11138102 | X3: 0.56872044 | Y3: 0.11399634 | Z3: -0.55833369 | AA3: 0.033401234 | AB3: -0.31697367 | AC3: 0.088148043 | AD3: -0.41851852 | AE3: 0.16627813 | AF3: -0.29407407 | AG3: 0.044971274 | AH3: -0.41 | AI3: 0.17363177 | AJ3: -0.31416346 | AK3: 0.028561545 | AL3: -0.49849224 | AM3: 0.16463482 | AN3: -0.60028613 | AO3: 0.15774925 | AP3: -0.6022819 | AQ3: 0.080607107 | AR3: -0.84893592 | AS3: 0.037207265 | AT3: -0.85819892 | AU3: 0.040517866 | AV3: -1.2741445 | AW3: 0.029575803 | AX3: -1.213209 | AY3: 0.05660347 | AZ3: -0.26319309 | BA3: 0.043707674 | BB3: 0.02969697 | BC3: 0.15118368 | BD3: 0.1859236 | BE3: 0.13011609 | BF3: 0.59023395 | BG3: 0.014900015 | BH3: 0.57111111 | BI3: 0.12460641 | BJ3: 0.67453195 | BK3: 0.031888693 | BL3: 0.79030835 | BM3: 0.07475219 | BN3: 0.67247372 | BO3: 0.11992912 | BP3: 1.1957904 | BQ3: 0.15920451 | BR3: 1.1944239 | BS3: 0.2241887 | BT3: 0.13814315 | BU3: 0.16510569 | BV3: 0.12578352 | BW3: 0.14828209 | BX3: 0.069596452 | BY3: 0.11726398 | BZ3: 0.22614075 | CA3: 0.12317168 | CB3: 0.3211372 | CC3: 0.20521346 | CD3: 0.35839848 | CE3: 0.18298687 | CF3: 0.41129559 | CG3: 0.14813766 | CH3: 0.57046757 | CI3: 0.061663028 | CJ3: 0.7851625 | CK3: 0.070258465 | CL3: 0.64209071 | CM3: 0.048557484 | CN3: 0.92700023 | CO3: 0.19233114 | CP3: 0.96856543 | CQ3: 0.17762145 | CR3: 1.0281435 | CS3: 0.14541282 | CT3: 1.6231188 | CU3: 0.087522166 | CV3: 1.9741596 | CW3: 0.075106553 | CX3: 2.3260469 | CY3: 0.062253192 | CZ3: 2.5815605 | DA3: 0.067388871 | DB3: 2.6673582 | DC3: 0.03299486 | DD3: 2.6729243 | DE3: 0.10239294 | DF3: 2.9212792 | DG3: 0.028005102 | DH3: 2.9479107 | DI3: 0.049791246 | DJ3: 2.6697087 | DK3: 0.16694326 | DL3: 2.9775765 | DM3: 0.20918639 | DN3: 3.2079414 | DO3: 0.039876298 | DP3: 3.096284 | DQ3: 0.87050605 | DR3: 3.2397133 | DS3: 0.21758845 | DT3: 3.2622803 | DU3: 0.73425839 | DV3: 1.9951389 | DW3: 1.6525703 | DX3: 1.0290543 | DY3: 0.18272784 | DZ3: 0.68853156 | EA3: 0.22827526 | EB3: 0.56982855 | EC3: 2.8720305 | ED3: -1.4053434 | EE3: 0.53234467 | EF3: -2.9891189 | EG3: 1.8058694 | EH3: -3.2269387 | EI3: 3.6099099 | EJ3: -4.7782642 | EK3: 20.040264 | EL3: -3.4804623 | EM3: 2.1235728 | EN3: -4.3634323 | EO3: 2.3657654 | EP3: -4.310595 | EQ3: 15.187817 | ER3: -4.096343 | ES3: 11.699336 | ET3: -2.7040158 | EU3: 13.187636 | EV3: -2.4214528 | EW3: 16.329346

Sheet Sheet1
A1: Station | C1: From | D1: To
A2: Carmelit | C2: 1964 | D2: 2025
A32: station | B32: x | C32: y | D32: 2025 | E32: 2024 | F32: 2023 | G32: 2022 | H32: 2021 | I32: 2020 | J32: 2019 | K32: 2018 | L32: 2017 | M32: 2016 | N32: 2015 | O32: 2014 | P32: 2013 | Q32: 2012 | R32: 2011 | S32: 2010 | T32: 2009 | U32: 2008 | V32: 2007 | W32: 2006 | X32: 2005 | Y32: 2004 | Z32: 2003 | AA32: 2002 | AB32: 2001 | AC32: 2000 | AD32: 1999 | AE32: 1998 | AF32: 1997 | AG32: 1996 | AH32: 1995 | AI32: 1994 | AJ32: 1993 | AK32: 1992 | AL32: 1991 | AM32: 1990 | AN32: 1989 | AO32: 1988 | AP32: 1987 | AQ32: 1986 | AR32: 1985 | AS32: 1984 | AT32: 1983 | AU32: 1982 | AV32: 1981 | AW32: 1980 | AX32: 1979 | AY32: 1978 | AZ32: 1977 | BA32: 1976 | BB32: 1975 | BC32: 1974 | BD32: 1973 | BE32: 1972 | BF32: 1971 | BG32: 1970 | BH32: 1969 | BI32: 1968 | BJ32: 1967 | BK32: 1966 | BL32: 1965 | BM32: 1964 | BN32: 1963 | BO32: 1962 | BP32: 1961 | BQ32: 1960 | BR32: 1959 | BS32: 1958 | BT32: 1957 | BU32: 1956 | BV32: 1955 | BW32: 1954 | BX32: 1953 | BY32: 1952 | BZ32: 1951 | CA32: 1950
A33: H. Terminus | B33: 177565 | C33: 659357 | D33: 2.815834 | E33: 2.4751335 | F33: 1.9009113 | G33: 1.9912911 | H33: 0.92453825 | I33: 1.0018968 | J33: 0.6675 | K33: 0.49222222 | L33: 0.7227149 | M33: 0.67176532 | N33: 0.61526873 | O33: 0.070709942 | P33: -0.60728925 | Q33: -1.2901965 | R33: -1.810983 | S33: -1.315535 | T33: -1.38 | U33: -1.1188501 | V33: -0.66045455 | W33: -1.5080622 | X33: -1.6368976 | Y33: -1.96676 | Z33: -1.8736174 | AA33: -1.9682279 | AB33: -1.9065028 | AC33: -1.2040626 | AD33: -0.79882734 | AE33: -0.6934995 | AF33: -0.89057679 | AG33: -0.94285437 | AH33: -0.77344641 | AI33: -1.3631439 | AJ33: -1.4421296 | AK33: -1.8598847 | AL33: -2.8145188 | AM33: -2.7771954 | AN33: -2.7133439 | AO33: -3.0083977 | AP33: -2.8325393 | AQ33: -2.7662701 | AR33: -2.1698917 | AS33: -1.7202744 | AT33: -1.3628371 | AU33: -1.4353661 | AV33: -1.0561104 | AW33: -1.0140092 | AX33: -1.1517635 | AY33: -0.19053749 | AZ33: -0.026835043 | BA33: 0.93868865 | BB33: 1.7503098 | BC33: 1.7327449 | BD33: 1.8280827 | BE33: 2.0326667 | BF33: 2.1141176 | BG33: 1.7694982 | BH33: 1.8056838 | BI33: 1.7465591 | BJ33: 1.9522986 | BK33: 2.0260601 | BL33: 2.9203664 | BM33: 2.1582645 | BN33: 1.9800166 | BO33: 1.3125117 | BP33: 1.751677 | BQ33: 1.4996055 | BR33: 1.2867061 | BS33: 2.2599098 | BT33: 2.6870147 | BU33: 2.3704702 | BV33: 2.1174973 | BW33: 1.5417717 | BX33: 2.5582019 | BY33: 3.6948791 | BZ33: 3.0026448 | CA33: 3.42142 | CB33: =MAX(D33:BM33) -> 2.9203664
A34: CO02 | B34: 177500 | C34: 659870 | D34: 2.3283179 | E34: 2.376348 | F34: 1.8672242 | G34: 1.8239942 | H34: 1.3481162 | I34: 1.148154 | J34: 0.70657128 | K34: 0.50705198 | L34: 0.72950252 | M34: 0.83956408 | N34: 0.64148019 | O34: 0.32102293 | P34: -0.27002217 | Q34: -1.0750801 | R34: -1.6269862 | S34: -0.42894987 | T34: -1.3490476 | U34: -0.33836429 | V34: -0.5575 | W34: -0.62313432 | X34: -0.99903796 | Y34: -1.3021779 | Z34: -1.2862066 | AA34: -1.2737712 | AB34: -1.0467412 | AC34: -0.49387504 | AD34: -0.27383177 | AE34: 0.032017424 | AF34: -0.22128299 | AG34: 0.098586211 | AH34: -0.20169773 | AI34: -0.92686631 | AJ34: -0.83061402 | AK34: -1.0932942 | AL34: -2.2659647 | AM34: -2.2953083 | AN34: -2.2377114 | AO34: -2.2452626 | AP34: -2.1713207 | AQ34: -2.0506366 | AR34: -1.602526 | AS34: -1.4623239 | AT34: -2.439562 | AU34: -0.89854881 | AV34: -0.31696451 | AW34: -0.069646271 | AX34: -0.61209657 | AY34: 0.21532273 | AZ34: 0.45075625 | BA34: 1.2307475 | BB34: 1.8463979 | BC34: 2.4479305 | BD34: 1.8328035 | BE34: 2.0713864 | BF34: 3.3110112 | BG34: 1.951614 | BH34: 2.0666429 | BI34: 2.1558993 | BJ34: 2.1154186 | BK34: 2.2761557 | BL34: 2.5527559 | BM34: 2.1561138 | BN34: 1.3631269 | BO34: 0.75491487 | BP34: 0.85453261 | BQ34: -0.19154151 | BR34: -0.26446954 | BS34: 0.36875191 | BT34: 3.3399925 | BU34: 1.9504582 | BV34: 1.5124909 | BW34: 1.5895833 | BX34: 1.197036 | BY34: 2.0450968 | BZ34: 2.806075 | CA34: 3.1381489 | CB34: =MAX(D34:BM34) -> 3.3110112
A35: Wolfson | B35: 177480 | C35: 660245 | D35: 2.4 | E35: 2.0346686 | F35: 1.6176612 | G35: 1.6759288 | H35: 1.5241341 | I35: 1.5424586 | J35: 0.89054939 | K35: 0.84066414 | L35: 0.84153846 | M35: 0.77615385 | N35: 0.66094664 | O35: 0.12137308 | P35: 0.034259947 | Q35: -0.58849853 | R35: -0.8682131 | S35: -0.17510393 | T35: -1.1713263 | U35: -0.10064541 | V35: -0.3517256 | W35: 0.069783256 | X35: -0.36695969 | Y35: -0.77191278 | Z35: -0.84637874 | AA35: -1.0935164 | AB35: -0.6038973 | AC35: -0.27291927 | AD35: -0.00087064752 | AE35: 0.3323569 | AF35: 0.1401883 | AG35: 0.46607251 | AH35: -0.009218151 | AI35: -0.76365258 | AJ35: -0.60657728 | AK35: -0.8603079 | AL35: -1.751375 | AM35: -1.8354423 | AN35: -1.694394 | AO35: -1.6029717 | AP35: -1.6419811 | AQ35: -1.5768339 | AR35: -1.2321055 | AS35: -1.0165511 | AT35: -2.0912745 | AU35: -0.59698095 | AV35: 0.03329595 | AW35: 0.23121913 | AX35: -0.16732842 | AY35: 0.86148124 | AZ35: 0.81505528 | BA35: 1.449929 | BB35: 1.9214595 | BC35: 2.5329521 | BD35: 2.0559831 | BE35: 2.4198345 | BF35: 3.5983169 | BG35: 2.6315203 | BH35: 2.4243692 | BI35: 2.5367917 | BJ35: 2.3976515 | BK35: 2.4277034 | BL35: 3.393991 | BM35: 2.0708957 | BN35: 1.0161386 | BO35: 0.81308554 | BP35: 0.077314624 | BQ35: -1.4501389 | BR35: -1.6021674 | BS35: -0.56496333 | BT35: 2.9298802 | BU35: 1.4141312 | BV35: 1.1200762 | BW35: 1.4464352 | BX35: 0.80219971 | BY35: 2.1103052 | BZ35: 2.5107132 | CA35: 2.9776326 | CB35: =MAX(D35:BM35) -> 3.5983169
A36: Nes Lagoyim | B36: 177730 | C36: 661270 | D36: 1.9 | E36: 1.8966831 | F36: 1.6728418 | G36: 1.9618029 | H36: 1.5929181 | I36: 1.2275186 | J36: 0.49352621 | K36: 0.38695034 | L36: 0.67351552 | M36: 0.54198334 | N36: 0.46034041 | O36: -0.1376155 | P36: -0.20154672 | Q36: -0.4825825 | R36: -0.21844062 | S36: -0.46769231 | T36: -0.38393699 | U36: -0.011936873 | V36: 0.048406524 | W36: -0.22981675 | X36: -0.49421892 | Y36: -0.61339264 | Z36: -0.67578476 | AA36: -0.85847248 | AB36: -0.2904128 | AC36: 0.032626174 | AD36: 0.61991792 | AE36: 0.57246873 | AF36: 0.51437723 | AG36: 0.44929609 | AH36: 0.69823315 | AI36: -0.4054085 | AJ36: 0.17502096 | AK36: 0.038069333 | AL36: -0.49792299 | AM36: -0.52686198 | AN36: -0.31201155 | AO36: -0.15460661 | AP36: -0.23992829 | AQ36: -0.31666076 | AR36: -0.21491448 | AS36: 0.30371138 | AT36: 0.33116962 | AU36: 0.28560394 | AV36: 0.73551986 | AW36: 0.70281736 | AX36: 0.67377497 | AY36: 2.6280405 | AZ36: 1.3735871 | BA36: 2.1594498 | BB36: 2.4219905 | BC36: 2.5358089 | BD36: 2.4872346 | BE36: 2.8031399 | BF36: 2.857738 | BG36: 2.753889 | BH36: 2.9488219 | BI36: 3.1930577 | BJ36: 3.1184768 | BK36: 3.1039545 | BL36: 3.3261662 | BM36: 2.0744412 | BN36: 1.1338208 | BO36: 0.66780789 | BP36: -0.095701421 | BQ36: -2.4228187 | BR36: -3.8448042 | BS36: -2.8501599 | BT36: -0.67011669 | BU36: -0.63515332 | BV36: -0.11002614 | BW36: 0.16826994 | BX36: -1.1300526 | BY36: 0.38679745 | BZ36: 0.61129459 | CB36: =MAX(D36:BM36) -> 3.3261662
A37: Shlavim | B37: 177980 | C37: 662360 | D37: 1.1 | E37: 1.9063392 | F37: 1.030907 | G37: 1.9009145 | H37: 1.3869107 | I37: 0.29206031 | J37: -0.20257656 | K37: 0.3406555 | L37: 0.37675191 | M37: 0.060955332 | N37: 0.56872044 | O37: -0.55833369 | P37: -0.31697367 | Q37: -0.41851852 | R37: -0.29407407 | S37: -0.41 | T37: -0.31416346 | U37: -0.49849224 | V37: -0.60028613 | W37: -0.6022819 | X37: -0.84893592 | Y37: -0.85819892 | Z37: -1.2741445 | AA37: -1.213209 | AB37: -0.26319309 | AC37: 0.02969697 | AD37: 0.1859236 | AE37: 0.59023395 | AF37: 0.57111111 | AG37: 0.67453195 | AH37: 0.79030835 | AI37: 0.67247372 | AJ37: 1.1957904 | AK37: 1.1944239 | AL37: 0.13814315 | AM37: 0.12578352 | AN37: 0.069596452 | AO37: 0.22614075 | AP37: 0.3211372 | AQ37: 0.35839848 | AR37: 0.41129559 | AS37: 0.57046757 | AT37: 0.7851625 | AU37: 0.64209071 | AV37: 0.92700023 | AW37: 0.96856543 | AX37: 1.0281435 | AY37: 1.6231188 | AZ37: 1.9741596 | BA37: 2.3260469 | BB37: 2.5815605 | BC37: 2.6673582 | BD37: 2.6729243 | BE37: 2.9212792 | BF37: 2.9479107 | BG37: 2.6697087 | BH37: 2.9775765 | BI37: 3.2079414 | BJ37: 3.096284 | BK37: 3.2397133 | BL37: 3.2622803 | BM37: 1.9951389 | BN37: 1.0290543 | BO37: 0.68853156 | BP37: 0.56982855 | BQ37: -1.4053434 | BR37: -2.9891189 | BS37: -3.2269387 | BT37: -4.7782642 | BU37: -3.4804623 | BV37: -4.3634323 | BW37: -4.310595 | BX37: -4.096343 | BY37: -2.7040158 | BZ37: -2.4214528 | CB37: =MAX(D37:BM37) -> 3.2622803
A38: Carmelit | B38: 178075 | C38: 663785 | D38: 0.6 | E38: 0.65580327 | F38: 1.1528641 | G38: 1.3975213 | H38: 0.72340895 | I38: 0.082609663 | J38: -0.31688067 | K38: 0.11538961 | L38: 0.21214857 | M38: -0.24910051 | N38: -0.027198864 | O38: 1.1217477 | P38: -0.54286109 | Q38: -0.59107022 | R38: -0.41873075 | S38: -0.4504226 | T38: -0.51121364 | U38: -0.60253846 | V38: -0.55303891 | W38: -0.71062539 | X38: -0.99528466 | Y38: -0.98390856 | Z38: -1.034893 | AA38: -1.1303514 | AB38: -0.36861799 | AC38: 0.022664941 | AD38: 0.10284347 | AE38: 0.1534186 | AF38: 0.44642021 | AG38: 0.42578278 | AH38: 0.69188552 | AI38: 0.84820314 | AJ38: 1.0914538 | AK38: 1.1596733 | AL38: 0.78149807 | AM38: 0.30005588 | AN38: 0.56180359 | AO38: 0.65469954 | AP38: 0.63904701 | AQ38: 0.64068335 | AR38: 0.69900505 | AS38: 0.742793 | AT38: 0.77741777 | AU38: 0.98620803 | AV38: 1.1661812 | AW38: 1.1372782 | AX38: 1.2793097 | AY38: 1.6442256 | AZ38: 1.6824018 | BA38: 2.0001015 | BB38: 2.4096574 | BC38: 2.5824094 | BD38: 2.6009417 | BE38: 2.7596016 | BF38: 2.8722676 | BG38: 2.6616072 | BH38: 3.0182958 | BI38: 2.9477019 | BJ38: 2.7211297 | BK38: 2.5426998 | BL38: 2.74357 | BM38: 1.5617628 | BN38: 1.1367378 | BO38: 0.88848374 | BP38: 0.89328044 | BQ38: -0.57941057 | BR38: -1.2308215 | BS38: -4.0365868 | BT38: -5.43875 | BU38: -5.1381071 | BV38: -4.8720512 | BW38: -4.7934849 | BX38: -5.2971732 | BY38: -5.0187907 | BZ38: -3.1798911 | CB38: =MAX(D38:BM38) -> 3.0182958
A39: Magen David | B39: 178555 | C39: 664210 | D39: 0.4 | E39: 0.40148326 | F39: 1.0792545 | G39: 1.1385158 | H39: 0.68631106 | I39: -0.093574804 | J39: -0.094074074 | K39: 0.53633333 | L39: 0.094451108 | M39: -0.036187423 | N39: 0.463 | O39: 1.1343333 | P39: -0.6932938 | Q39: -0.81874031 | R39: -0.34593614 | S39: -0.40918454 | T39: -0.49859319 | U39: -0.61806821 | V39: -0.50682325 | W39: -0.86998289 | X39: -1.061618 | Y39: -0.9819228 | Z39: -1.2524809 | AA39: -1.2938691 | AB39: -0.48212733 | AC39: -0.1027257 | AD39: 0.064772923 | AE39: 0.23407464 | AF39: 0.58148148 | AG39: 0.70013356 | AH39: 0.85610557 | AI39: 0.74187804 | AJ39: 1.1646775 | AK39: 1.7348669 | AL39: 1.0303372 | AM39: 0.38661015 | AN39: 0.48612965 | AO39: 0.34597576 | AP39: 1.1711905 | AQ39: 1.1216875 | AR39: 1.184197 | AS39: 0.476322 | AT39: 0.6237411 | AU39: 0.58704364 | AV39: 1.7343659 | AW39: 1.5256262 | AX39: 1.6442537 | AY39: 1.867453 | AZ39: 2.4793927 | BA39: 2.4676467 | BB39: 2.6392245 | BC39: 2.6856686 | BD39: 2.6202889 | BE39: 3.0601316 | BF39: 2.8483935 | BG39: 2.7486834 | BH39: 3.3264919 | BI39: 3.5420282 | BJ39: 3.7438632 | BK39: 3.0161416 | BL39: 2.632973 | BM39: 1.4964791 | BN39: 1.623819 | BO39: 0.68241127 | BP39: 0.4121117 | BQ39: -0.51048058 | BR39: -1.6437296 | BS39: -2.985294 | BT39: -4.9770356 | BU39: -4.9600937 | BV39: -4.2212933 | BW39: -5.1855556 | BX39: -5.2017643 | BY39: -5.3067921 | BZ39: -2.6864994 | CB39: =MAX(D39:BM39) -> 3.7438632
A40: Habima | B40: 179300 | C40: 664390 | D40: 0.4 | E40: 0.56864919 | F40: 1.0232462 | G40: 0.96684009 | H40: 0.4876452 | I40: -0.25602479 | J40: -0.46693048 | K40: 0.65625 | L40: 0.21457324 | M40: -0.28853244 | N40: 0.15948406 | O40: 1.54375 | P40: -0.90462179 | Q40: -1.0605002 | R40: -0.64095418 | S40: -0.48146403 | T40: -0.53992486 | U40: -0.55617708 | V40: -0.61011436 | W40: -0.91416964 | X40: -1.0558486 | Y40: -1.0921818 | Z40: -1.2174545 | AA40: -1.2056498 | AB40: -0.55758974 | AC40: -0.11724387 | AD40: -0.041764343 | AE40: 0.23281041 | AF40: 0.60721128 | AG40: 0.6599799 | AH40: 0.8116483 | AI40: 1.2511136 | AJ40: 1.7692857 | AK40: 1.5638733 | AL40: 0.80226964 | AM40: 0.82151515 | AN40: 0.51749379 | AO40: 0.33583333 | AP40: 0.27768755 | AQ40: 0.20579828 | AR40: 0.61602161 | AS40: 0.21474359 | AT40: 0.32458333 | AU40: 0.3897169 | AV40: 0.90142672 | AW40: 0.60280327 | AX40: 0.93297122 | AY40: 1.2945731 | AZ40: 1.3934242 | BA40: 1.3768792 | BB40: 1.778566 | BC40: 1.8323025 | BD40: 2.4993132 | BE40: 2.2620727 | BF40: 2.418695 | BG40: 2.8604757 | BH40: 2.800806 | BI40: 3.4387809 | BJ40: 3.2739237 | BK40: 2.5803122 | BL40: 2.8318502 | BM40: 1.4072238 | BN40: 0.45336057 | BO40: 0.67133468 | BP40: 0.26347725 | BQ40: -0.59891965 | BR40: -1.9493093 | BS40: -4.2363887 | BT40: -6.2804346 | BU40: -6.4160488 | BV40: -5.0040063 | BW40: -5.3411111 | BX40: -4.2183293 | BY40: -4.4858478 | BZ40: -3.2475808 | CB40: =MAX(D40:BM40) -> 3.4387809
A41: Hashmonaim | B41: 179910 | C41: 664090 | D41: 0.7 | E41: 1.238114 | F41: 0.8834902 | G41: 0.76597299 | H41: 0.30891208 | I41: -0.42869128 | J41: -0.404 | K41: 0.23272727 | L41: 0.095618394 | M41: -0.12249299 | N41: -0.017235475 | O41: 0.96636364 | P41: -0.87818182 | Q41: -1.0263636 | R41: -0.66271908 | S41: -0.34137394 | T41: -0.41657051 | U41: -0.58088753 | V41: -0.62342373 | W41: -0.89018977 | X41: -1.0943803 | Y41: -1.127109 | Z41: -1.2688172 | AA41: -1.1763729 | AB41: -0.63109091 | AC41: 0.090259529 | AD41: 0.31284174 | AE41: 0.62340597 | AF41: 0.47008775 | AG41: 0.71377825 | AH41: 1.1800304 | AI41: 1.1142157 | AJ41: 1.590098 | AK41: 1.3690564 | AL41: 0.62919905 | AM41: 0.71897436 | AN41: 0.4931051 | AO41: 0.18621816 | AP41: 0.51219392 | AQ41: 0.4836785 | AR41: 0.62476018 | AS41: 0.39273529 | AT41: 0.66976036 | AU41: 0.63740239 | AV41: 1.0532471 | AW41: 0.84567 | AX41: 1.0512071 | AY41: 1.5217964 | AZ41: 1.6395135 | BA41: 1.809705 | BB41: 2.1967687 | BC41: 2.2483751 | BD41: 2.5371357 | BE41: 2.2411632 | BF41: 2.6133414 | BG41: 2.7913456 | BH41: 3.1331798 | BI41: 3.6584009 | BJ41: 3.4775333 | BK41: 2.7057822 | BL41: 2.3475959 | BM41: 1.1495745 | BN41: 0.10230275 | BO41: 0.45533476 | BP41: -0.34764862 | BQ41: -1.0466257 | BR41: -2.3663756 | BS41: -5.9122306 | BT41: -5.7533201 | BU41: -6.0890909 | BV41: -6.2405284 | BW41: -5.4377778 | BX41: -5.0703018 | BY41: -4.1210803 | BZ41: -3.0968896 | CA41: 1.4234304 | CB41: =MAX(D41:BM41) -> 3.6584009
A42: Kikar Noga | B42: 182060 | C42: 664730 | D42: 1.1 | E42: =AVERAGE(F42,D42) -> 0.77772689 | F42: 0.45545378 | G42: 0.11350299 | H42: -0.31742137 | I42: -0.61201481 | J42: -1.3154579 | K42: -0.62394001 | L42: 0.36813161 | M42: -0.11639298 | N42: -1.4880664 | O42: -0.90865143 | P42: -1.2137025 | Q42: -1.4771659 | R42: -0.99716587 | S42: -1.1154548 | T42: -1.2463912 | U42: -1.2898007 | V42: -1.2351677 | W42: -1.406871 | X42: -1.4377984 | Y42: -1.3936437 | Z42: -1.7115525 | AA42: -1.7819189 | AB42: -1.1378779 | AC42: -0.77101602 | AD42: -0.59263026 | AE42: -0.0913872 | AF42: 0.39961827 | AG42: 0.6790625 | AH42: 0.38011714 | AI42: 0.3443741 | AJ42: 0.72552859 | AK42: 0.45972895 | AL42: -0.31068905 | AM42: -0.53179315 | AN42: -0.72585305 | AO42: -0.98305085 | AP42: -1.0436891 | AQ42: -1.4211514 | AR42: -1.4508654 | AS42: -1.218328 | AT42: -1.2232838 | AU42: -1.1213434 | AV42: -1.1121818 | AW42: -1.2521365 | AX42: -0.79024354 | AY42: -0.26466383 | AZ42: 0.037267453 | BA42: 0.20195746 | BB42: 0.50423039 | BC42: 0.16006765 | BD42: 1.0182565 | BE42: 1.016598 | BF42: 1.1511295 | BG42: 0.88666855 | BH42: 0.86784787 | BI42: 3.0278125 | BJ42: 2.2166371 | BK42: 1.8838559 | BL42: -0.90512013 | BM42: -2.275516 | BN42: -1.5520003 | BO42: -2.0247077 | BP42: -1.9547397 | BQ42: -2.4271664 | BR42: -3.0608062 | BS42: -4.4489817 | BT42: -3.3321325 | BU42: -2.8689064 | BV42: -3.3855003 | BW42: -2.739802 | BX42: -0.78657777 | BY42: -0.21742328 | BZ42: 0.18927092 | CA42: 0.81343056 | CB42: =MAX(D42:BM42) -> 3.0278125
A43: Katznelson | B43: 182880 | C43: 664770 | D43: 1.5 | E43: 0.97779988 | F43: 0.16941533 | G43: 0.50044585 | H43: -0.21680978 | I43: -0.63649495 | J43: -1.1981227 | K43: 0.019626546 | L43: -0.52745898 | M43: -0.75447434 | N43: -0.6827279 | O43: -1.0189661 | P43: -1.2089019 | Q43: -1.2801642 | R43: -0.97914115 | S43: -0.98175012 | T43: -1.1443839 | U43: -1.2521102 | V43: -1.4666784 | W43: -1.5518473 | X43: -1.7457981 | Y43: -1.7520823 | Z43: -1.9173258 | AA43: -1.8808486 | AB43: -1.2780403 | AC43: -0.95173445 | AD43: -0.64879222 | AE43: -0.11548605 | AF43: 0.25359449 | AG43: 0.77660734 | AH43: 0.10681272 | AI43: 0.26144916 | AJ43: 0.56988729 | AK43: 0.3527374 | AL43: -0.42089859 | AM43: -1.0260818 | AN43: -0.85599386 | AO43: -1.0740013 | AP43: -1.5335907 | AQ43: -1.8408147 | AR43: -1.5260611 | AS43: -1.3996744 | AT43: -0.97726481 | AU43: -1.3195854 | AV43: -1.1896373 | AW43: -1.1686917 | AX43: -0.70977247 | AY43: -0.32068472 | AZ43: 0.31940608 | BA43: -0.51546493 | BB43: -1.7822832 | BC43: -1.8351268 | BD43: -1.179199 | BE43: -0.96519505 | BF43: -0.16842154 | BG43: 4.3083744 | BH43: 3.7539046 | BI43: 3.0461538 | BJ43: 0.86137385 | BK43: 0.95076886 | BL43: -2.1754744 | BM43: -3.1370923 | BN43: -3.0274248 | BO43: -2.4991651 | BP43: -2.3444444 | BQ43: -3.5927544 | BR43: -5.5567891 | BS43: -4.8805424 | BT43: -3.8904477 | BU43: -3.2586806 | BV43: -0.36830942 | BW43: -0.35893314 | BX43: 0.7795743 | BY43: 0.27048626 | BZ43: 1.8604406 | CA43: 2.2134756 | CB43: =MAX(D43:BM43) -> 4.3083744
A44: Haroe | B44: 183745 | C44: 664640 | D44: 1.9 | E44: 2.045416 | F44: 0.89297815 | G44: 1.8263618 | H44: 0.95615135 | I44: 0.44094581 | J44: -0.42979006 | K44: 0.36048805 | L44: 0.17098845 | M44: -0.19430216 | N44: 0.14009406 | O44: -0.38425374 | P44: -0.43267837 | Q44: -0.29842242 | R44: -0.31499523 | S44: -0.24734268 | T44: -0.27261487 | U44: -0.56683316 | V44: -1.3706982 | W44: -1.1770756 | X44: -1.5155153 | Y44: -1.4459958 | Z44: -1.7070905 | AA44: -1.4728046 | AB44: -1.2110266 | AC44: -0.50324687 | AD44: -0.089420216 | AE44: 0.53691802 | AF44: 0.84971247 | AG44: 1.124851 | AH44: 0.596935 | AI44: 1.0546127 | AJ44: 1.1785419 | AK44: 0.61218772 | AL44: -0.4221018 | AM44: -0.76944295 | AN44: -0.76594892 | AO44: -0.69018967 | AP44: -0.92816966 | AQ44: -1.3963456 | AR44: -0.91829897 | AS44: -0.92528597 | AT44: -0.96255008 | AU44: -0.60811063 | AV44: -0.75118342 | AW44: -0.93195484 | AX44: -0.48387133 | AY44: -0.16494291 | AZ44: 0.6136094 | BA44: 0.69629391 | BB44: 1.2484584 | BC44: 0.65433488 | BD44: 0.15675165 | BE44: 0.53154539 | BF44: 0.92966836 | BG44: 4.8517211 | BH44: 4.778048 | BI44: 4.2407092 | BJ44: 4.784406 | BK44: 2.2529175 | BL44: -1.1303984 | BM44: -1.9092708 | BN44: -1.866831 | BO44: -1.6866789 | BP44: -1.6759086 | BQ44: -2.3850968 | BR44: -2.0226908 | BS44: -1.5765654 | BT44: -0.78227324 | BU44: 0.20679149 | BV44: 2.5693933 | BW44: 2.8465249 | BX44: 2.7253298 | BY44: 0.95238037 | BZ44: 3.6658497 | CA44: 3.4676532 | CB44: =MAX(D44:BM44) -> 4.8517211
A45: Hazon Ish | B45: 184485 | C45: 664790 | D45: 2.6 | E45: 2.8686351 | F45: 2.0792602 | G45: 2.4711579 | H45: 2.2571515 | I45: 1.7251732 | J45: 0.90054665 | K45: 1.2359466 | L45: 1.104952 | M45: 1.1756214 | N45: 1.1986203 | O45: 0.71547996 | P45: 0.65680199 | Q45: 0.70335335 | R45: 0.9817268 | S45: 0.84296573 | T45: 1.0176458 | U45: 0.4814976 | V45: -0.4777312 | W45: -0.34706049 | X45: -0.2953414 | Y45: -0.43396704 | Z45: -0.85366483 | AA45: -0.75924482 | AB45: -0.56903991 | AC45: 0.58919134 | AD45: 0.99020143 | AE45: 1.4486004 | AF45: 1.5251609 | AG45: 1.6113641 | AH45: 1.1797988 | AI45: 1.9406676 | AJ45: 2.2310878 | AK45: 1.3148764 | AL45: -0.10491727 | AM45: -0.34217154 | AN45: -0.24651124 | AO45: -0.24263499 | AP45: -0.22866837 | AQ45: -0.7713834 | AR45: -0.50258071 | AS45: -0.47229415 | AT45: -0.60973823 | AU45: -0.29420389 | AV45: -0.4181064 | AW45: -0.45961756 | AX45: -0.037412952 | AY45: 0.38718823 | AZ45: 0.71825046 | BA45: 0.76811784 | BB45: 1.2221978 | BC45: 0.80850192 | BD45: 2.1400694 | BE45: 2.4449014 | BF45: 2.6241644 | BG45: 4.5100121 | BH45: 1.8522614 | BI45: 4.0400369 | BJ45: 4.358506 | BK45: 0.70390702 | BL45: -1.4432425 | BM45: -2.0959696 | BN45: -1.8233066 | BO45: -1.5476754 | BP45: -1.395275 | BQ45: -1.0965942 | BR45: -0.92779 | BS45: -0.1303639 | BT45: 0.73609346 | BU45: 1.8337748 | BV45: 2.4257753 | BW45: 3.708556 | BX45: 4.1132388 | BY45: 3.3619143 | BZ45: 4.6300243 | CA45: 4.4014697 | CB45: =MAX(D45:BM45) -> 4.5100121
A46: CO06 | B46: 184850 | C46: 664800 | D46: 3.1102627 | E46: 3.3516292 | F46: 2.9081923 | G46: 2.8289236 | H46: 2.8177141 | I46: 2.3047122 | J46: 1.8099442 | K46: 2.2243425 | L46: 1.8249732 | M46: 1.9074041 | N46: 1.787861 | O46: 1.2819533 | P46: 1.3517287 | Q46: 1.350842 | R46: 1.5221705 | S46: 1.01558 | T46: 1.1092698 | U46: 1.0619191 | V46: 0.30134601 | W46: 0.43814509 | X46: 0.60063471 | Y46: 0.30594769 | Z46: -0.28551044 | AA46: -0.22655182 | AB46: 0.31779136 | AC46: 1.3762394 | AD46: 1.6192723 | AE46: 1.8865993 | AF46: 1.9361349 | AG46: 2.1094158 | AH46: 1.7212486 | AI46: 2.579697 | AJ46: 2.8414748 | AK46: 1.9453273 | AL46: 0.23185477 | AM46: 0.041908241 | AN46: 0.097744752 | AO46: 0.12140366 | AP46: 0.25295233 | AQ46: -0.21713729 | AR46: -0.10332546 | AS46: -0.013007768 | AT46: -0.044457964 | AU46: -0.063943259 | AV46: -0.0028190242 | AW46: -0.022391172 | AX46: 0.32154793 | AY46: 0.93410226 | AZ46: 1.0762314 | BA46: 1.0797968 | BB46: 1.2060453 | BC46: 1.0154134 | BD46: 2.1013546 | BE46: 2.324085 | BF46: 2.4302821 | BG46: 3.3092455 | BH46: 2.4492122 | BI46: 3.966 | BJ46: 1.4612672 | BK46: 1.0280347 | BL46: -1.2943462 | BM46: -1.62892 | BN46: -1.261881 | BO46: -1.0559468 | BP46: -0.86716148 | BQ46: -0.49672258 | BR46: -0.07392386 | BS46: 0.36416653 | BT46: 1.3713796 | BU46: 2.2093371 | BV46: 2.7888534 | BW46: 5.3876819 | BX46: 4.8472329 | BY46: 4.3308121 | BZ46: 5.4529885 | CA46: 4.9358564 | CB46: =MAX(D46:BM46) -> 3.966
A47: Kahneman | B47: 185320 | C47: 664775 | D47: 4.9 | E47: 4.0454518 | F47: 3.5503052 | G47: 4.0186452 | H47: 3.271897 | I47: 3.2621384 | J47: 3.1355385 | K47: 3.2281838 | L47: 3.3441683 | M47: 3.3284484 | N47: 3.1772085 | O47: 3.1961846 | P47: 2.9613393 | Q47: 2.8411362 | R47: 3.1263922 | S47: 2.4574135 | T47: 2.9017557 | U47: 2.3291725 | V47: 1.867819 | W47: 2.0179132 | X47: 1.6749234 | Y47: 1.2286342 | Z47: 0.4921169 | AA47: 0.61710394 | AB47: 1.570725 | AC47: 2.2832683 | AD47: 2.8722715 | AE47: 2.9756621 | AF47: 2.9111024 | AG47: 3.2774949 | AH47: 2.81838 | AI47: 3.6051858 | AJ47: 3.6769835 | AK47: 2.7002396 | AL47: 0.92139654 | AM47: 0.77607988 | AN47: 0.73845182 | AO47: 0.72908704 | AP47: 0.86408652 | AQ47: 0.65543646 | AR47: 0.71046498 | AS47: 0.76348214 | AT47: 0.64811556 | AU47: 0.24710885 | AV47: 0.56403675 | AW47: 0.70795482 | AX47: 0.95234431 | AY47: 1.5686577 | AZ47: 1.4817429 | BA47: 1.4575527 | BB47: 1.7072999 | BC47: 1.8598621 | BD47: 2.1459202 | BE47: 2.5449412 | BF47: 2.2874941 | BG47: 1.6814885 | BH47: 0.95454667 | BI47: 1.2305956 | BJ47: -0.30381388 | BK47: -0.24341845 | BL47: -1.1811242 | BM47: -1.4308139 | BN47: -1.1678442 | BO47: -0.94196693 | BP47: -0.45436723 | BQ47: 0.28807463 | BR47: 0.67873158 | BS47: 1.3255728 | BT47: 2.8432365 | BU47: 3.3502202 | BV47: 3.4715885 | BW47: 5.352829 | BX47: 5.365209 | BY47: 5.325956 | BZ47: 5.9955545 | CA47: 5.8953752 | CB47: =MAX(D47:BM47) -> 4.9
A48: Bar Ilan | B48: 185935 | C48: 664560 | D48: 6.5 | E48: 6.292483 | F48: 6.0704328 | G48: 5.5188584 | H48: 5.3534455 | I48: 4.7015072 | J48: 4.6444574 | K48: 4.9588717 | L48: 5.1168596 | M48: 5.0615227 | N48: 4.8795844 | O48: 4.570499 | P48: 4.3653228 | Q48: 3.992554 | R48: 4.893301 | S48: 4.9620203 | T48: 4.5791378 | U48: 4.0211146 | V48: 3.6442786 | W48: 3.8894407 | X48: 3.6989975 | Y48: 3.1627432 | Z48: 2.5771117 | AA48: 3.0125743 | AB48: 4.1115326 | AC48: 4.4442452 | AD48: 5.3523296 | AE48: 5.57495 | AF48: 5.7339144 | AG48: 5.6041043 | AH48: 5.3653599 | AI48: 5.4338494 | AJ48: 5.3383095 | AK48: 4.3011717 | AL48: 2.6677955 | AM48: 2.4697165 | AN48: 2.3527113 | AO48: 2.2847206 | AP48: 2.2719395 | AQ48: 2.1220099 | AR48: 2.2057077 | AS48: 2.1091776 | AT48: 1.7950854 | AU48: 0.92054555 | AV48: 1.6873495 | AW48: 1.9140928 | AX48: 2.0705501 | AY48: 2.4868793 | AZ48: 2.4929254 | BA48: 2.5369648 | BB48: 2.9619368 | BC48: 3.0911779 | BD48: 3.4089451 | BE48: 3.2734126 | BF48: 3.2499037 | BG48: 3.5827812 | BH48: 1.849786 | BI48: 2.0265883 | BJ48: 0.37676843 | BK48: 1.087065 | BL48: -0.24850633 | BM48: -0.37142939 | BN48: -0.20052556 | BO48: -0.13866483 | BP48: 0.77316979 | BQ48: 1.635173 | BR48: 1.6999246 | BS48: 3.2943253 | BT48: 4.4895635 | BU48: 4.8229396 | BV48: 8.6402973 | BW48: 5.9620693 | BX48: 6.4077397 | BY48: 6.7750323 | BZ48: 11.757187 | CA48: 12.92138 | CB48: =MAX(D48:BM48) -> 6.5
A49: Kfar Ganim | B49: 186860 | C49: 664515 | D49: 10 | E49: 10.030863 | F49: 9.4843768 | G49: 9.1777903 | H49: 8.9002734 | I49: 7.8223198 | J49: 8.1913827 | K49: 8.157248 | L49: 8.3732705 | M49: 8.3618843 | N49: 7.9128392 | O49: 7.5951376 | P49: 7.5175959 | Q49: 7.9113628 | R49: 8.0136514 | S49: 8.5181017 | T49: 8.2562826 | U49: 8.0859816 | V49: 8.2712402 | W49: 8.4306268 | X49: 8.3411669 | Y49: 7.9571818 | Z49: 7.6835914 | AA49: 7.9473812 | AB49: 9.0847527 | AC49: 9.1365583 | AD49: 6.3822034 | AE49: 6.9758302 | AF49: 7.4104446 | AG49: 6.6269166 | AH49: 6.3891305 | AI49: 6.8921562 | AJ49: 6.7676645 | AK49: 4.5338615 | AL49: 6.0619554 | AM49: 6.652852 | AN49: 6.385592 | AO49: 5.4573968 | AP49: 5.3553465 | AQ49: 5.5342893 | AR49: 5.4866695 | AS49: 5.5552307 | AT49: 5.8944489 | AU49: 4.2010756 | AV49: 4.7174368 | AW49: 4.1153884 | AX49: 4.2169299 | AY49: 5.5788698 | AZ49: 5.6008559 | BA49: 5.7941855 | BB49: 5.14241 | BC49: 4.720616 | BD49: 4.3689725 | BE49: 3.5979091 | BF49: 3.8038852 | BG49: 3.7757373 | BH49: 3.3777764 | BI49: 2.922041 | BJ49: 3.2168035 | BK49: 3.9272331 | BL49: 3.7179009 | BM49: 3.9503324 | BN49: 4.3565594 | BO49: 4.6412991 | BP49: 5.061573 | BQ49: 4.8347315 | BR49: 4.6577238 | BS49: 5.6232595 | BT49: 6.2779321 | BU49: 6.5887561 | BV49: 11.224504 | BW49: 7.1911387 | BX49: 7.7164747 | BY49: 8.0821674 | BZ49: 14.512239 | CA49: 12.786574 | CB49: =MAX(D49:BM49) -> 10.030863
A50: Ben Gurion | B50: 187910 | C50: 664940 | D50: 12.8 | E50: 12.616983 | F50: 12.426279 | G50: 11.694282 | H50: 11.68493 | I50: 11.484506 | J50: 11.211602 | K50: 11.108887 | L50: 11.474033 | M50: 11.326206 | N50: 11.190495 | O50: 11.111052 | P50: 11.747951 | Q50: 12.015165 | R50: =AVERAGE(P50,T50) -> 12.411227 | S50: 13.188807 | T50: 13.074504 | U50: 13.215842 | V50: 13.311181 | W50: 13.334895 | X50: 13.605243 | Y50: 12.892564 | Z50: 12.884931 | AA50: 13.569589 | AB50: 14.066252 | AC50: 14.244065 | AD50: =AVERAGE(AB50,AF50) -> 14.06281 | AE50: 14.161272 | AF50: 14.059369 | AG50: 13.720714 | AH50: 13.431731 | AI50: 13.235048 | AJ50: 13.167859 | AK50: 12.502832 | AL50: 11.186405 | AM50: 11.359425 | AN50: 11.064862 | AO50: 10.801705 | AP50: 10.644754 | AQ50: 10.564711 | AR50: 10.51816 | AS50: 10.482118 | AT50: 11.075252 | AU50: 9.3665544 | AV50: 9.1838715 | AW50: 5.7066826 | AX50: 6.8395987 | AY50: 9.4750882 | AZ50: 7.9445735 | BA50: 9.0854692 | BB50: 8.1718418 | BC50: 7.3269659 | BD50: 6.4618261 | BE50: 6.03411 | BF50: 6.1835975 | BG50: 5.454158 | BH50: 5.3780285 | BI50: 5.1158299 | BJ50: 5.7492252 | BK50: 6.0991038 | BL50: 5.8613921 | BM50: 6.9957507 | BN50: 7.5372355 | BO50: 8.3391773 | BP50: 8.6451263 | BQ50: 9.2324341 | BR50: 7.7962701 | BS50: 9.6913523 | BT50: 9.5820421 | BU50: 9.9631447 | BV50: 11.638889 | BW50: 8.983112 | BX50: 9.3740404 | BY50: 9.5230034 | BZ50: 37.935279 | CA50: 39.799524 | CB50: =MAX(D50:BM50) -> 14.244065
A51: Arlozorov | B51: 188545 | C51: 665800 | D51: 14.931102 | E51: 14.937401 | F51: 13.242387 | G51: 13.805731 | H51: 13.583721 | I51: 13.280819 | J51: 11.542863 | K51: 11.325545 | L51: 13.156593 | M51: 11.553271 | N51: 11.647595 | O51: 11.688693 | P51: 13.49427 | Q51: 13.242035 | R51: 11.823649 | S51: 14.906996 | T51: 15.236624 | U51: 15.489601 | V51: 15.542195 | W51: 15.634751 | X51: 15.780541 | Y51: 15.882974 | Z51: 15.971805 | AA51: 16.000933 | AB51: 16.148036 | AC51: 16.29299 | AD51: 14.025997 | AE51: 16.32681 | AF51: 16.220963 | AG51: 16.077771 | AH51: 15.888705 | AI51: 15.654694 | AJ51: 15.58895 | AK51: 15.161572 | AL51: 14.231547 | AM51: 14.349812 | AN51: 14.149903 | AO51: 13.862291 | AP51: 13.641837 | AQ51: 13.485793 | AR51: 13.439029 | AS51: 13.299509 | AT51: 13.065447 | AU51: 12.403097 | AV51: 12.353822 | AW51: 11.4745 | AX51: 11.707188 | AY51: 12.339862 | AZ51: 11.339435 | BA51: 11.624391 | BB51: 11.659902 | BC51: 11.156012 | BD51: 10.30873 | BE51: 10.211944 | BF51: 9.8521114 | BG51: 9.5504554 | BH51: 9.5090607 | BI51: 9.3580333 | BJ51: 9.7889014 | BK51: 10.008104 | BL51: 10.137961 | BM51: 10.383961 | BN51: 10.96474 | BO51: 11.285475 | BP51: 11.684671 | BQ51: 12.149445 | BR51: 12.078237 | BS51: 13.117702 | BT51: 13.070735 | BU51: 13.223206 | BV51: 14.063333 | BW51: 10.582053 | BX51: 11.229532 | BY51: 7.8506351 | BZ51: 11.491752 | CA51: 16.77625 | CB51: =MAX(D51:BM51) -> 16.32681
A52: PT City Hall | B52: 189450 | C52: 665915 | D52: 17.5 | E52: 18.399508 | F52: 14.911839 | G52: 14.796602 | H52: 14.993504 | I52: 14.745549 | J52: =AVERAGE(J51,J53) -> 12.902557 | K52: 11.673226 | L52: 13.215778 | M52: 11.93912 | N52: 12.109459 | O52: 12.157074 | P52: 14.263404 | Q52: 13.702862 | R52: =AVERAGE(P52,T52) -> 15.107644 | S52: 15.573588 | T52: 15.951884 | U52: 16.27134 | V52: 16.488061 | W52: 16.709921 | X52: 16.908619 | Y52: 16.948598 | Z52: 17.008717 | AA52: 16.730753 | AB52: 16.804073 | AC52: 17.165815 | AD52: 14.925509 | AE52: 17.65039 | AF52: 17.918982 | AG52: 18.026487 | AH52: 18.044784 | AI52: 18.000217 | AJ52: 17.292725 | AK52: 16.991252 | AL52: 14.289345 | AM52: 13.926159 | AN52: 13.726421 | AO52: 15.355819 | AP52: 14.123792 | AQ52: 15.047077 | AR52: 15.05375 | AS52: 15.591192 | AT52: 15.61853 | AU52: 14.134236 | AV52: 13.970055 | AW52: 13.867568 | AX52: 10.770777 | AY52: 10.104944 | AZ52: 13.622864 | BA52: 14.360253 | BB52: 13.945246 | BC52: 14.079841 | BD52: 13.15771 | BE52: 15.247835 | BF52: 14.460063 | BG52: 14.362919 | BH52: 14.3814 | BI52: 14.659767 | BJ52: 15.226307 | BK52: 15.372397 | BL52: 15.298903 | BM52: 15.389468 | BN52: 16.891291 | BO52: 17.105794 | BP52: 17.521442 | BQ52: 17.727373 | BR52: 18.777786 | BS52: 18.372083 | BT52: 17.487986 | BU52: 16.806827 | BV52: 16.892222 | BW52: 14.426287 | BX52: 16.488763 | BY52: 11.904836 | BZ52: 13.210511 | CA52: 23.270476 | CB52: =MAX(D52:BM52) -> 18.399508
A53: PT East | B53: 190980 | C53: 665533 | D53: 18.2 | E53: 16.491822 | F53: 15.659303 | G53: 16.687067 | H53: 17.417491 | I53: 15.307186 | J53: 14.26225 | K53: 13.231846 | L53: 12.817521 | M53: 13.945006 | N53: 13.977034 | O53: 13.445814 | P53: 14.986067 | Q53: 13.816708 | R53: 14.355614 | S53: 14.720599 | T53: 15.224561 | U53: 15.561889 | V53: 16.28492 | W53: 16.629186 | X53: 16.597674 | Y53: 16.363312 | Z53: 16.341908 | AA53: 15.60566 | AB53: 15.107535 | AC53: 15.912505 | AD53: 13.786518 | AE53: 18.04799 | AF53: 18.25075 | AG53: 18.784824 | AH53: 18.994135 | AI53: 19.294456 | AJ53: 19.774847 | AK53: 18.669875 | AL53: 14.434591 | AM53: 14.630984 | AN53: 14.765371 | AO53: 15.289405 | AP53: 14.953577 | AQ53: 13.527708 | AR53: 14.93125 | AS53: 16.627617 | AT53: 16.662205 | AU53: 15.741635 | AV53: 16.109 | AW53: 17.245801 | AX53: 14.779642 | AY53: 14.766974 | AZ53: 16.66636 | BA53: 16.70252 | BB53: 17.667198 | BC53: 17.883616 | BD53: 17.609612 | BE53: 18.411035 | BF53: 18.391114 | BG53: 18.531927 | BH53: 18.829113 | BI53: 18.593919 | BJ53: 19.237978 | BK53: 18.826097 | BL53: 19.137198 | BM53: 19.193662 | BN53: 20.145625 | BO53: 20.291131 | BP53: 20.710384 | BQ53: 21.253724 | BR53: 23.213023 | BS53: 22.449926 | BT53: 21.572818 | BU53: 21.840892 | BV53: 22.227998 | BW53: 21.25983 | BX53: 26.049653 | BY53: 22.391015 | BZ53: 22.504933 | CB53: =MAX(D53:BM53) -> 19.774847
A54: Sirkin South | B54: 191750 | C54: 665670 | D54: 17.3 | E54: 16.868865 | F54: 15.755146 | G54: 17.452227 | H54: 17.544686 | I54: 15.746038 | J54: 13.843872 | K54: 11.637653 | L54: 11.385899 | M54: 12.800523 | N54: 13.29845 | O54: 13.583858 | P54: 15.37826 | Q54: 12.878964 | R54: 12.046461 | S54: 13.311581 | T54: 14.081866 | U54: 14.649859 | V54: 14.94306 | W54: 15.671813 | X54: 16.084596 | Y54: 15.934527 | Z54: 15.176597 | AA54: 14.332727 | AB54: 14.26455 | AC54: 14.865641 | AD54: 14.26689 | AE54: 17.823149 | AF54: 18.662141 | AG54: 19.359135 | AH54: 19.762857 | AI54: 19.827793 | AJ54: 20.62266 | AK54: 19.157525 | AL54: 13.551737 | AM54: 13.9013 | AN54: 14.5781 | AO54: 15.32798 | AP54: 14.606133 | AQ54: 13.517603 | AR54: 15.131945 | AS54: 17.603143 | AT54: 17.205556 | AU54: 15.753507 | AV54: 17.223333 | AW54: 17.094486 | AX54: 15.262273 | AY54: 16.515487 | AZ54: 16.952647 | BA54: 16.915538 | BB54: 18.455602 | BC54: 18.203296 | BD54: 17.87178 | BE54: 18.307088 | BF54: 18.0775 | BG54: 18.412769 | BH54: 18.9725 | BI54: 18.334654 | BJ54: 18.612067 | BK54: 18.232422 | BL54: 18.833048 | BM54: 18.131319 | BN54: 18.686958 | BO54: 19.429857 | BP54: 19.481074 | BQ54: 19.986788 | BR54: 21.374132 | BS54: 22.58646 | BT54: 22.297381 | BU54: 22.758889 | BV54: 22.85 | BW54: 22.306053 | BX54: 23.735863 | BY54: 24.207385 | BZ54: 24.437123 | CB54: =MAX(D54:BM54) -> 20.62266
A55: CO09 | B55: 191875 | C55: 665980 | D55: 17.157913 | E55: 17.762825 | F55: 15.741224 | G55: 17.452227 | H55: 17.374037 | I55: 15.771832 | J55: 13.752833 | K55: 11.571586 | L55: 11.201433 | M55: 12.619704 | N55: 13.00035 | O55: 13.595879 | P55: 13.800957 | Q55: 12.878964 | R55: 12.046461 | S55: 13.19765 | T55: 13.591033 | U55: 14.333293 | V55: 15.151677 | W55: 16.011282 | X55: 15.844605 | Y55: 15.938333 | Z55: 14.815617 | AA55: 14.112777 | AB55: 13.905272 | AC55: 14.436866 | AD55: 14.264111 | AE55: 17.872331 | AF55: 18.642098 | AG55: 19.365852 | AH55: 19.771784 | AI55: 20.114233 | AJ55: 21.589551 | AK55: 19.773681 | AL55: 13.162664 | AM55: 13.514321 | AN55: 14.182155 | AO55: 15.324391 | AP55: 14.25722 | AQ55: 13.392025 | AR55: 15.632132 | AS55: 17.576404 | AT55: 17.44501 | AU55: 16.885556 | AV55: 17.378182 | AW55: 16.967597 | AX55: 15.382009 | AY55: 16.719501 | AZ55: 16.994981 | BA55: 16.954643 | BB55: 17.730356 | BC55: 18.087422 | BD55: 17.926355 | BE55: 18.313333 | BF55: 17.935698 | BG55: 17.797033 | BH55: 18.587179 | BI55: 18.338 | BJ55: 17.982504 | BK55: 18.096 | BL55: 18.657 | BM55: 17.460379 | BN55: 20.343541 | BO55: 19.057903 | BP55: 19.442443 | BQ55: 19.718859 | BR55: 20.839806 | BS55: 22.461247 | BT55: 22.225588 | BU55: 22.799992 | BV55: 22.85 | BW55: 22.281401 | BX55: 23.523062 | BY55: 24.417013 | BZ55: 24.356626 | CB55: =MAX(D55:BM55) -> 21.589551
A56: Sirkin North | B56: 192070 | C56: 666800 | D56: 16.5 | E56: 19.926701 | F56: 14.799246 | G56: 16.919316 | H56: 16.748797 | I56: 15.52125 | J56: 13.564334 | K56: 12.143794 | L56: 11.615622 | M56: 12.598736 | N56: 13.00407 | O56: 12.644953 | P56: 13.734679 | Q56: 12.84 | R56: 11.632691 | S56: 11.500482 | T56: 12.581198 | U56: =AVERAGE(U55,U57) -> 13.810053 | V56: 14.023262 | W56: 15.168889 | X56: 15.727835 | Y56: 15.64 | Z56: 14.335518 | AA56: 10.895 | AB56: 11.104098 | AC56: 12.381887 | AD56: 13.43507 | AE56: 17.201666 | AF56: 18.483926 | AG56: 19.32312 | AH56: 19.804444 | AI56: 20.39436 | AJ56: 21.651111 | AK56: 19.775 | AL56: 12.330428 | AM56: 12.575 | AN56: 14.260924 | AO56: 15.14875 | AP56: 14.315 | AQ56: 13.092222 | AR56: 14.323 | AS56: 17.439 | AT56: 17.492321 | AU56: 16.167 | AV56: 17.959069 | AW56: 16.9375 | AX56: 15.540038 | AY56: 17.074255 | AZ56: 17.106061 | BA56: 17.27816 | BB56: 18.336543 | BC56: 18.587778 | BD56: 17.935034 | BE56: 18.453396 | BF56: 18.345473 | BG56: 18.27683 | BH56: 17.875607 | BI56: 17.864787 | BJ56: 18.385125 | BK56: 17.557539 | BL56: 18.27411 | BM56: 16.906823 | BN56: 19.092316 | BO56: 18.682411 | BP56: 19.163495 | BQ56: 19.353742 | BR56: 21.018924 | BS56: 22.402354 | BT56: 22.325659 | BU56: 22.665556 | BV56: 22.703224 | BW56: 23.001841 | BX56: 23.647289 | BY56: 24.277622 | BZ56: 23.964275 | CB56: =MAX(D56:BM56) -> 21.651111
A57: Depo | B57: 191000 | C57: 668000 | D57: 15 | E57: 18.753191 | F57: 18.978565 | G57: 15.816171 | H57: 11.862238 | I57: 14.288733 | J57: 13.621452 | K57: 11.493992 | L57: 11.194132 | M57: 13.011346 | N57: 13.28119 | O57: 11.840162 | P57: 13.625 | Q57: 12.406038 | R57: 11.274502 | S57: 11.802332 | T57: 12.69556 | U57: 13.286814 | V57: 14.942528 | W57: 15.895481 | X57: 15.77694 | Y57: 15.802323 | Z57: 14.863358 | AA57: 12.53742 | AB57: 12.595844 | AC57: 13.566886 | AD57: 13.491269 | AE57: 16.431323 | AF57: 16.742004 | AG57: 17.540708 | AH57: 18.024163 | AI57: 18.078452 | AJ57: 18.630902 | AK57: 17.690649 | AL57: 13.456138 | AM57: 12.905798 | AN57: 13.648274 | AO57: 15.13002 | AP57: 14.431604 | AQ57: 13.943179 | AR57: 14.889378 | AS57: 17.384355 | AT57: 17.664732 | AU57: 15.136395 | AV57: 17.254872 | AW57: 15.911767 | AX57: 14.701269 | AY57: 17.504745 | AZ57: 17.403409 | BA57: 17.398168 | BB57: 19.572453 | BC57: 18.734348 | BD57: 16.719169 | BE57: 18.074739 | BF57: 17.704061 | BG57: 18.205464 | BH57: 18.550001 | BI57: 17.203152 | BJ57: 17.583584 | BK57: 17.626126 | BL57: 17.551701 | BM57: 16.662 | BN57: 17.805418 | BO57: 18.098841 | BP57: 18.130187 | BQ57: 18.929143 | BR57: 20.481836 | BS57: 21.687065 | BT57: 21.323642 | BU57: 21.868888 | BV57: 21.346197 | BW57: 21.357485 | BX57: 19.617887 | BY57: 19.83438 | BZ57: 19.746118 | CB57: =MAX(D57:BM57) -> 19.572453
D59: =D32 -> 2025 | E59: =E32 -> 2024 | F59: =F32 -> 2023 | G59: =G32 -> 2022 | H59: =H32 -> 2021 | I59: =I32 -> 2020 | J59: =J32 -> 2019 | K59: =K32 -> 2018 | ... CA59: =CA32 -> 1950
D60: {=IF(AND(D32<=$D$2,D32>=$C$2),OFFSET(D$32,MATCH($A$2,$A$33:$A$57,0),0),_xleta.N/A())} -> 0.6 | E60: {=IF(AND(E32<=$D$2,E32>=$C$2),OFFSET(E$32,MATCH($A$2,$A$33:$A$57,0),0),_xleta.N/A())} -> 0.65580327 | F60: {=IF(AND(F32<=$D$2,F32>=$C$2),OFFSET(F$32,MATCH($A$2,$A$33:$A$57,0),0),_xleta.N/A())} -> 1.1528641 | G60: {=IF(AND(G32<=$D$2,G32>=$C$2),OFFSET(G$32,MATCH($A$2,$A$33:$A$57,0),0),_xleta.N/A())} -> 1.3975213 | H60: {=IF(AND(H32<=$D$2,H32>=$C$2),OFFSET(H$32,MATCH($A$2,$A$33:$A$57,0),0),_xleta.N/A())} -> 0.72340895 | I60: {=IF(AND(I32<=$D$2,I32>=$C$2),OFFSET(I$32,MATCH($A$2,$A$33:$A$57,0),0),_xleta.N/A())} -> 0.082609663 | J60: {=IF(AND(J32<=$D$2,J32>=$C$2),OFFSET(J$32,MATCH($A$2,$A$33:$A$57,0),0),_xleta.N/A())} -> -0.31688067 | K60: {=IF(AND(K32<=$D$2,K32>=$C$2),OFFSET(K$32,MATCH($A$2,$A$33:$A$57,0),0),_xleta.N/A())} -> 0.11538961 | ... CA60: {=IF(AND(CA32<=$D$2,CA32>=$C$2),OFFSET(CA$32,MATCH($A$2,$A$33:$A$57,0),0),_xleta.N/A())} -> #VALUE!
D61: 2025 | E61: 2024 | F61: 2023 | G61: 2022 | H61: 2021 | I61: 2020 | J61: 2019 | K61: 2018 | L61: 2017 | M61: 2016 | N61: 2015 | O61: 2014 | P61: 2013 | Q61: 2012 | R61: 2011 | S61: 2010 | T61: 2009 | U61: 2008 | V61: 2007 | W61: 2006 | X61: 2005 | Y61: 2004 | Z61: 2003 | AA61: 2002 | AB61: 2001 | AC61: 2000 | AD61: 1999 | AE61: 1998 | AF61: 1997 | AG61: 1996 | AH61: 1995 | AI61: 1994 | AJ61: 1993 | AK61: 1992 | AL61: 1991 | AM61: 1990 | AN61: 1989 | AO61: 1988 | AP61: 1987 | AQ61: 1986 | AR61: 1985 | AS61: 1984 | AT61: 1983 | AU61: 1982 | AV61: 1981 | AW61: 1980 | AX61: 1979 | AY61: 1978 | AZ61: 1977 | BA61: 1976 | BB61: 1975 | BC61: 1974 | BD61: 1973 | BE61: 1972 | BF61: 1971 | BG61: 1970 | BH61: 1969 | BI61: 1968 | BJ61: 1967 | BK61: 1966 | BL61: 1965 | BM61: 1964 | BN61: 1963 | BO61: 1962 | BP61: 1961 | BQ61: 1960 | BR61: 1959 | BS61: 1958 | BT61: 1957 | BU61: 1956 | BV61: 1955 | BW61: 1954 | BX61: 1953 | BY61: 1952 | BZ61: 1951 | CA61: 1950
D62: {=_xlfn._xlws.FILTER(D59:CA59, (D59:CA59 >= C2) * (D59:CA59 <= D2))} -> 2025 | E62: 2024 | F62: 2023 | G62: 2022 | H62: 2021 | I62: 2020 | J62: 2019 | K62: 2018 | L62: 2017 | M62: 2016 | N62: 2015 | O62: 2014 | P62: 2013 | Q62: 2012 | R62: 2011 | S62: 2010 | T62: 2009 | U62: 2008 | V62: 2007 | W62: 2006 | X62: 2005 | Y62: 2004 | Z62: 2003 | AA62: 2002 | AB62: 2001 | AC62: 2000 | AD62: 1999 | AE62: 1998 | AF62: 1997 | AG62: 1996 | AH62: 1995 | AI62: 1994 | AJ62: 1993 | AK62: 1992 | AL62: 1991 | AM62: 1990 | AN62: 1989 | AO62: 1988 | AP62: 1987 | AQ62: 1986 | AR62: 1985 | AS62: 1984 | AT62: 1983 | AU62: 1982 | AV62: 1981 | AW62: 1980 | AX62: 1979 | AY62: 1978 | AZ62: 1977 | BA62: 1976 | BB62: 1975 | BC62: 1974 | BD62: 1973 | BE62: 1972 | BF62: 1971 | BG62: 1970 | BH62: 1969 | BI62: 1968 | BJ62: 1967 | BK62: 1966 | BL62: 1965 | BM62: 1964
D63: {=_xlfn._xlws.FILTER(D60:CA60, (D59:CA59 >= C2) * (D59:CA59 <= D2))} -> 0.6 | E63: 0.65580327 | F63: 1.1528641 | G63: 1.3975213 | H63: 0.72340895 | I63: 0.082609663 | J63: -0.31688067 | K63: 0.11538961 | L63: 0.21214857 | M63: -0.24910051 | N63: -0.027198864 | O63: 1.1217477 | P63: -0.54286109 | Q63: -0.59107022 | R63: -0.41873075 | S63: -0.4504226 | T63: -0.51121364 | U63: -0.60253846 | V63: -0.55303891 | W63: -0.71062539 | X63: -0.99528466 | Y63: -0.98390856 | Z63: -1.034893 | AA63: -1.1303514 | AB63: -0.36861799 | AC63: 0.022664941 | AD63: 0.10284347 | AE63: 0.1534186 | AF63: 0.44642021 | AG63: 0.42578278 | AH63: 0.69188552 | AI63: 0.84820314 | AJ63: 1.0914538 | AK63: 1.1596733 | AL63: 0.78149807 | AM63: 0.30005588 | AN63: 0.56180359 | AO63: 0.65469954 | AP63: 0.63904701 | AQ63: 0.64068335 | AR63: 0.69900505 | AS63: 0.742793 | AT63: 0.77741777 | AU63: 0.98620803 | AV63: 1.1661812 | AW63: 1.1372782 | AX63: 1.2793097 | AY63: 1.6442256 | AZ63: 1.6824018 | BA63: 2.0001015 | BB63: 2.4096574 | BC63: 2.5824094 | BD63: 2.6009417 | BE63: 2.7596016 | BF63: 2.8722676 | BG63: 2.6616072 | BH63: 3.0182958 | BI63: 2.9477019 | BJ63: 2.7211297 | BK63: 2.5426998 | BL63: 2.74357 | BM63: 1.5617628
BQ65: H. Terminus | BR65: 2.9203664
BQ66: CO02 | BR66: 3.3110112
BQ67: Wolfson | BR67: 3.5983169
BQ68: Nes Lagoyim | BR68: 3.3261662
BQ69: Shlavim | BR69: 3.2622803
BQ70: Carmelit | BR70: 3.0182958
BQ71: Magen David | BR71: 3.7438632
...

Sheet Sheet2
A1: Wolfson | B1: =MATCH($A$1,Sheet1!$A$33:$A$57,0) -> 3 | C1: =MATCH(A3,Sheet1!$D$61:$CA$61,0) -> 76
A3: 1950 | B3: =OFFSET(Sheet1!$A$32,MATCH($A$1,Sheet1!$A$33:$A$57,0),MATCH(A3,Sheet1!$D$61:$CA$61,0)+2) -> 2.9776326
A4: 1951 | B4: =OFFSET(Sheet1!$A$32,MATCH($A$1,Sheet1!$A$33:$A$57,0),MATCH(A4,Sheet1!$D$61:$CA$61,0)+2) -> 2.5107132
A5: 1952 | B5: =OFFSET(Sheet1!$A$32,MATCH($A$1,Sheet1!$A$33:$A$57,0),MATCH(A5,Sheet1!$D$61:$CA$61,0)+2) -> 2.1103052
A6: 1953 | B6: =OFFSET(Sheet1!$A$32,MATCH($A$1,Sheet1!$A$33:$A$57,0),MATCH(A6,Sheet1!$D$61:$CA$61,0)+2) -> 0.80219971
A7: 1954 | B7: =OFFSET(Sheet1!$A$32,MATCH($A$1,Sheet1!$A$33:$A$57,0),MATCH(A7,Sheet1!$D$61:$CA$61,0)+2) -> 1.4464352
A8: 1955 | B8: =OFFSET(Sheet1!$A$32,MATCH($A$1,Sheet1!$A$33:$A$57,0),MATCH(A8,Sheet1!$D$61:$CA$61,0)+2) -> 1.1200762
A9: 1956 | B9: =OFFSET(Sheet1!$A$32,MATCH($A$1,Sheet1!$A$33:$A$57,0),MATCH(A9,Sheet1!$D$61:$CA$61,0)+2) -> 1.4141312
A10: 1957 | B10: =OFFSET(Sheet1!$A$32,MATCH($A$1,Sheet1!$A$33:$A$57,0),MATCH(A10,Sheet1!$D$61:$CA$61,0)+2) -> 2.9298802
A11: 1958 | B11: =OFFSET(Sheet1!$A$32,MATCH($A$1,Sheet1!$A$33:$A$57,0),MATCH(A11,Sheet1!$D$61:$CA$61,0)+2) -> -0.56496333
A12: 1959 | B12: =OFFSET(Sheet1!$A$32,MATCH($A$1,Sheet1!$A$33:$A$57,0),MATCH(A12,Sheet1!$D$61:$CA$61,0)+2) -> -1.6021674
A13: 1960 | B13: =OFFSET(Sheet1!$A$32,MATCH($A$1,Sheet1!$A$33:$A$57,0),MATCH(A13,Sheet1!$D$61:$CA$61,0)+2) -> -1.4501389
A14: 1961 | B14: =OFFSET(Sheet1!$A$32,MATCH($A$1,Sheet1!$A$33:$A$57,0),MATCH(A14,Sheet1!$D$61:$CA$61,0)+2) -> 0.077314624
... A85: 2032 | B85: =OFFSET(Sheet1!$A$32,MATCH($A$1,Sheet1!$A$33:$A$57,0),MATCH(A85,Sheet1!$D$61:$CA$61,0)+2) -> #N/A
